<?xml version="1.0" ?>
<!-- =================================================================================== -->
<!-- |    This document was autogenerated by xacro from /home/bridge/Bridge_hub/leg_db_ws/src/legged_debugger/legged_examples/legged_base/legged_base_description/urdf/robot_sim.xacro | -->
<!-- |    EDITING THIS FILE BY HAND IS NOT RECOMMENDED                                 | -->
<!-- =================================================================================== -->
<robot name="RobotDog">
  <!-- ros_control plugin -->
  <gazebo>
    <plugin filename="liblegged_hw_sim.so" name="gazebo_ros_control">
      <robotNamespace>/</robotNamespace>
      <robotParam>legged_robot_description</robotParam>
      <robotSimType>legged_gazebo/LeggedHWSim</robotSimType>
    </plugin>
  </gazebo>
  <gazebo>
    <plugin filename="libgazebo_ros_p3d.so" name="p3d_base_controller">
      <alwaysOn>true</alwaysOn>
      <updateRate>500.0</updateRate>
      <bodyName>base</bodyName>
      <topicName>ground_truth/state</topicName>
      <gaussianNoise>0</gaussianNoise>
      <frameName>world</frameName>
      <xyzOffsets>0 0 0</xyzOffsets>
      <rpyOffsets>0 0 0</rpyOffsets>
    </plugin>
  </gazebo>
  <link name="base">
    <visual>
      <origin xyz="0 0 0" rpy="0 0 0" />
      <geometry>
        <mesh filename="package://legged_fire_description/meshes/Base.STL" />
      </geometry>
      <!-- <material name="">
        <color rgba="0.79216 0.81961 0.93333 1" />
      </material> -->
      <material name="grey"/>
    </visual>
    <!-- <collision>
      <origin xyz="0.025 0 0" rpy="0 0 0" />
      <geometry>
        <mesh filename="/home/bridge/amp_ppo_ws/src/legged_gym_amp_ppo/src/AMP_for_hardware/resources/robots/LT/meshes/Base.STL" />
        <box size="1.075 0.10 0.18"/>
      </geometry>
    </collision> -->
    <collision>
      <origin xyz="0.0 0 0" rpy="0 0 0" />
      <geometry>
        <box size="0.55 0.28 0.18"/>
      </geometry>
    </collision>
    <collision>
      <origin xyz="0.42 0 0" rpy="0 0 0" />
      <geometry>
        <box size="0.25 0.12 0.18"/>
      </geometry>
    </collision>
    <collision>
      <origin xyz="-0.40 0 0" rpy="0 0 0" />
      <geometry>
        <box size="0.20 0.12 0.18"/>
      </geometry>
    </collision>
    <inertial>
      <origin xyz="0.0 0.0 0.0" rpy="0 0 0" />
      <mass value="12.40" />
      <inertia ixx="0.1632" ixy="0.0" ixz="0.0" iyy="0.342653" iyz="0.0" izz="0.39432" />
    </inertial>
  </link>
  <!-- Imu is fixed to the base link -->
  <joint name="base_imu_joint" type="fixed">
    <origin rpy="0. 0. 0." xyz="0. 0. 0."/>
    <parent link="base"/>
    <child link="base_imu"/>
  </joint>
  <gazebo reference="base_imu_joint">
    <disableFixedJointLumping>true</disableFixedJointLumping>
  </gazebo>
  <!-- Imu link -->
  <link name="base_imu">
    <inertial>
      <mass value="0.01"/>
      <origin rpy="0 0 0" xyz="0 0 0"/>
      <inertia ixx="0.000001" ixy="0" ixz="0" iyy="0.000001" iyz="0" izz="0.000001"/>
    </inertial>
    <visual>
      <origin rpy="0 0 0" xyz="0 0 0"/>
      <geometry>
        <box size="0.015 0.015 0.004"/>
      </geometry>
    </visual>
    <material name="orange">
      <color rgba="255 108 10 255"/>
    </material>
  </link>
 
  <joint name="FR_hip_joint" type="revolute">
    <origin xyz="0.2655 -0.076 0" rpy="0 0 0" />
    <parent link="base" />
    <child link="FR_hip" />
    <axis xyz="1 0 0" />
    <dynamics damping="0.0" bfriction="0.2"/>
    <limit effort="80.0" lower="-1" upper="1" velocity="30.1"/>
  </joint>
  <link name="FR_hip">
    <visual>
      <origin xyz="0 0 0" rpy="0 0 0" />
      <geometry>
        <mesh filename="package://legged_fire_description/meshes/FR_Hip.STL" />
      </geometry>
      <!-- <material name="">
        <color rgba="0.79216 0.81961 0.93333 1" />
      </material> -->
      <material name="blue"/>
    </visual>
    <!-- <collision>
      <origin rpy="1.5707963267948966 0 0" xyz="0 0 0"/>
      <geometry>
        <cylinder length="0.0587" radius="0.077"/>
      </geometry>
    </collision> -->
    <inertial>
      <origin xyz="0.12 -0.005 0.0" rpy="0 0 0" />
      <mass value="2.640" />
      <inertia ixx="0.0049" ixy="0.0" ixz="0.0" iyy="0.0065" iyz="0.0" izz="0.0049" />
    </inertial>
  </link>
  <joint name="FR_thigh_joint" type="revolute">
    <origin xyz="0.121 -0.013 0" rpy="0 0 0" />
    <parent link="FR_hip" />
    <child link="FR_thigh" />
    <axis xyz="0 1 0" />
    <dynamics damping="0.0" bfriction="0.2"/>
    <limit effort="80.0" lower="-3" upper="4.501" velocity="30.1"/>
  </joint>
  <link name="FR_thigh">
    <visual>
      <origin xyz="0 0 0" rpy="0 0 0" />
      <geometry>
        <mesh filename="package://legged_fire_description/meshes/HR_Thigh.STL" />
      </geometry>
      <!-- <material name="">
        <color rgba="0.79216 0.81961 0.93333 1" />
      </material> -->
      <material name="green"/>
    </visual>
    <collision>
      <origin xyz="0 -0.11 0" rpy="1.57 0 0" />
      <geometry>
        <cylinder length="0.12" radius="0.07"/>
      </geometry>
    </collision>
    <collision>
      <origin xyz="-0.035 -0.14 -0.16" rpy="0 0 0" />
      <geometry>
        <box size="0.055 0.06 0.20"/>
      </geometry>
    </collision>
    <collision>
      <origin xyz="-0.017 -0.14 -0.325" rpy="0 -0.40 0" />
      <geometry>
        <box size="0.030 0.06 0.13"/>
      </geometry>
    </collision>
    <!-- <collision>
      <origin rpy="1.5707963267948966 0 0" xyz="0 -0.0 0"/>
      <geometry>
        <cylinder length="0.0587" radius="0.077"/>
      </geometry>
    </collision> -->
    <inertial>
      <origin xyz="-0.0 -0.11 -0.16" rpy="0 0 0" />
      <mass value="4.170" />
      <inertia ixx="0.071" ixy="0.0" ixz="0.0" iyy="0.077" iyz="0.0" izz="0.0081" />
    </inertial>
  </link>
  <joint name="FR_calf_joint" type="revolute">
    <origin xyz="0.0 -0.11514 -0.36702" rpy="0 0 0" />
    <parent link="FR_thigh" />
    <child link="FR_calf" />
    <axis xyz="0 1 0" />
    <dynamics damping="0.0" bfriction="0.2"/>
    <limit effort="80.0" lower="-2.818" upper="0" velocity="20.06"/>
  </joint>
  <link name="FR_calf">
    <visual>
      <origin xyz="0 0 0" rpy="0 0 0" />
      <geometry>
        <mesh filename="package://legged_fire_description/meshes/FR_Knee.STL" />
      </geometry>
      <!-- <material name="">
        <color rgba="0.79216 0.81961 0.93333 1" />
      </material> -->
      <material name="brown"/>
    </visual>
    <!-- <collision>
      <origin xyz="0 0 0" rpy="0 0 0" />
      <geometry>
        <mesh filename="/home/bridge/amp_ppo_ws/src/legged_gym_amp_ppo/src/AMP_for_hardware/resources/robots/LT/meshes/FR_Knee.STL" />
      </geometry>
    </collision> -->
    <!-- <collision>
      <origin xyz="-0.01 -0.02 -0.07" rpy="0 -0.40 0" />
      <geometry>
        <box size="0.02 0.04 0.18"/>
      </geometry>
    </collision> -->
    <collision>
      <origin xyz="0.03 -0.02 -0.23" rpy="0 0 0" />
      <geometry>
        <box size="0.02 0.04 0.10"/>
      </geometry>
    </collision>
    <inertial>
      <origin xyz="0.0 -0.0225 -0.16" rpy="0 0 0" />
      <mass value="0.715" />
      <inertia ixx="0.0062" ixy="0.0" ixz="0.0" iyy="0.0062" iyz="0.0" izz="0.000133" />
    </inertial>
  </link>
  <joint name="FR_foot_fixed" type="fixed" dont_collapse="true">
    <origin xyz="0.0051604 -0.021519 -0.33117" rpy="0 0 0" />
    <parent link="FR_calf" />
    <child link="FR_FOOT" />
    <axis xyz="0 0 0" />
  </joint>
  <gazebo reference="FR_foot_fixed">
    <disableFixedJointLumping>true</disableFixedJointLumping>
  </gazebo>
  <link name="FR_FOOT">
    <visual>
      <origin xyz="0 0 0" rpy="0 0.62 0" />
      <geometry>
        <mesh filename="package://legged_fire_description/meshes/FR_Ankle.STL" />
      </geometry>
      <!-- <material name="">
        <color rgba="0 0 0 1" />
      </material> -->
      <material name="black"/>
    </visual>
    <collision>
      <origin xyz="-0.010 0 -0.017" rpy="0 0 0" />
      <geometry>
        <sphere radius="0.022"/>
      </geometry>
    </collision>
    <inertial>
      <origin xyz="-0.012 0.0 -0.0175" rpy="0 0.62 0" />
      <mass value="0.05" />
      <inertia ixx="0.000008" ixy="0.0" ixz="0.0" iyy="0.000008" iyz="0.0" izz="0.000008" />
    </inertial>
  </link>
  <joint name="FL_hip_joint" type="revolute">
    <origin xyz="0.2655 0.076 0" rpy="0 0 0" />
    <parent link="base" />
    <child link="FL_hip" />
    <axis xyz="1 0 0" />
    <dynamics damping="0.0" bfriction="0.2"/>
    <limit effort="80.0" lower="-1" upper="1" velocity="30.1"/>
  </joint>
  <link name="FL_hip">
    <visual>
      <origin xyz="0 0 0" rpy="0 0 0" />
      <geometry>
        <mesh filename="package://legged_fire_description/meshes/FL_Hip.STL" />
      </geometry>
      <!-- <material name="">
        <color rgba="0.79216 0.81961 0.93333 1" />
      </material> -->
      <material name="blue"/>
    </visual>
     <!-- <collision>
      <origin xyz="0 0 0" rpy="0 0 0" />
      <geometry>
        <mesh filename="package://legged_fire_description/meshes/FL_Hip.STL" />
      </geometry>
    </collision> -->
    <inertial>
      <origin xyz="0.12 0.005 -0.0" rpy="0 0 0" />
      <mass value="2.640" />
      <inertia ixx="0.0049" ixy="0.0" ixz="0.0" iyy="0.0065" iyz="0.0" izz="0.0049" />
    </inertial>
  </link>
  <joint name="FL_thigh_joint" type="revolute">
    <origin xyz="0.121 0.013 0" rpy="0 0 0" />
    <parent link="FL_hip" />
    <child link="FL_thigh" />
    <axis xyz="0 1 0" />
    <dynamics damping="0.0" bfriction="0.2"/>
    <limit effort="80.0" lower="-3" upper="4.501" velocity="30.1"/>
  </joint>
  <link name="FL_thigh">
    <visual>
      <origin xyz="0 0 0" rpy="0 0 0" />
      <geometry>
        <mesh filename="package://legged_fire_description/meshes/FL_Thigh.STL" />
      </geometry>
      <!-- <material name="">
        <color rgba="0.79216 0.81961 0.93333 1" />
      </material> -->
      <material name="green"/>
    </visual>
    <collision>
      <origin xyz="0 0.11 0" rpy="1.57 0 0" />
      <geometry>
        <cylinder length="0.12" radius="0.07"/>
      </geometry>
    </collision>
    <collision>
      <origin xyz="-0.035 0.14 -0.16" rpy="0 0 0" />
      <geometry>
        <box size="0.055 0.06 0.20"/>
      </geometry>
    </collision>
    <collision>
      <origin xyz="-0.017 0.14 -0.325" rpy="0 -0.40 0" />
      <geometry>
        <box size="0.030 0.06 0.13"/>
      </geometry>
    </collision>
    <inertial>
      <origin xyz="-0.0 0.11 -0.16" rpy="0 0 0" />
      <mass value="4.170" />
      <inertia ixx="0.071" ixy="0.0" ixz="0.0" iyy="0.077" iyz="0.0" izz="0.0081" />
    </inertial>
  </link>
  <joint name="FL_calf_joint" type="revolute">
    <origin xyz="0 0.11514 -0.36702" rpy="0 0 0" />
    <parent link="FL_thigh" />
    <child link="FL_calf" />
    <axis xyz="0 1 0" />
    <dynamics damping="0.0" bfriction="0.2"/>
    <limit effort="80.0" lower="-2.818" upper="0" velocity="20.06"/>
  </joint>
  <link name="FL_calf">
    <visual>
      <origin xyz="0 0 0" rpy="0 0 0" />
      <geometry>
        <mesh filename="package://legged_fire_description/meshes/FL_Knee.STL" />
      </geometry>
      <!-- <material name="">
        <color rgba="0.79216 0.81961 0.93333 1" />
      </material> -->
      <material name="brown"/>
    </visual>
    <collision>
      <origin xyz="0.03 0.02 -0.23" rpy="0 0 0" />
      <geometry>
        <box size="0.02 0.04 0.10"/>
      </geometry>
    </collision>
    <inertial>
      <origin xyz="0.0 0.0225 -0.16" rpy="0 0 0" />
      <mass value="0.715" />
      <inertia ixx="0.0062" ixy="0.0" ixz="0.0" iyy="0.0062" iyz="0.0" izz="0.000133" />
    </inertial>
  </link>
  <joint name="FL_foot_fixed" type="fixed" dont_collapse="true">
    <origin xyz="0.0051604 0.021519 -0.33117" rpy="0 0 0" />
    <parent link="FL_calf" />
    <child link="FL_FOOT" />
    <axis xyz="0 0 0" />
  </joint>
  <gazebo reference="FL_foot_fixed">
    <disableFixedJointLumping>true</disableFixedJointLumping>
  </gazebo>
  <link name="FL_FOOT">
    <visual>
      <origin xyz="0 0 0" rpy="0 0.62 0" />
      <geometry>
        <mesh filename="package://legged_fire_description/meshes/FL_Ankle.STL" />
      </geometry>
      <!-- <material name="">
        <color rgba="0 0 0 1" />
      </material> -->
      <material name="black"/>
    </visual>
    <!-- <collision>
      <origin xyz="0 0 0" rpy="0 0 0" />
      <geometry>
        <mesh filename="package://legged_fire_description/meshes/FL_Ankle.STL" />
      </geometry>
    </collision> -->
    <collision>
      <origin xyz="-0.010 0 -0.017" rpy="0 0 0" />
      <geometry>
        <sphere radius="0.022"/>
      </geometry>
    </collision>
    <inertial>
      <origin xyz="-0.012 0.0 -0.0175" rpy="0 0.62 0" />
      <mass value="0.05" />
      <inertia ixx="0.000008" ixy="0.0" ixz="0.0" iyy="0.000008" iyz="0.0" izz="0.000008" />
    </inertial>
  </link>
  <joint name="RR_hip_joint" type="revolute">
    <origin xyz="-0.2655 -0.076 0" rpy="0 0 0" />
    <parent link="base" />
    <child link="RR_hip" />
    <axis xyz="1 0 0" />
    <dynamics damping="0.0" bfriction="0.2"/>
    <limit effort="80.0" lower="-1" upper="1" velocity="30.1"/>
  </joint>
  <link name="RR_hip">
    <visual>
      <origin xyz="0 0 0" rpy="0 0 0" />
      <geometry>
        <mesh filename="package://legged_fire_description/meshes/FR_Hip.STL" />
      </geometry>
      <!-- <material name="">
        <color rgba="0.79216 0.81961 0.93333 1" />
      </material> -->
      <material name="blue"/>
    </visual>
    <!-- <collision>
      <origin xyz="0 0 0" rpy="0 0 0" />
      <geometry>
        <mesh filename="package://legged_fire_description/meshes/FR_Hip.STL" />
      </geometry>
    </collision> -->
    <inertial>
      <origin xyz="-0.12 -0.005 -0.0" rpy="0 0 0" />
      <mass value="2.640" />
      <inertia ixx="0.0049" ixy="0.0" ixz="0.0" iyy="0.0065" iyz="0.0" izz="0.0049" />
    </inertial>
  </link>
  <joint name="RR_thigh_joint" type="revolute">
    <origin xyz="-0.121 -0.013 0" rpy="0 0 0" />
    <parent link="RR_hip" />
    <child link="RR_thigh" />
    <axis xyz="0 1 0" />
    <dynamics damping="0.0" bfriction="0.2"/>
    <limit effort="80.0" lower="-3" upper="4.501" velocity="30.1"/>
  </joint>
  <link name="RR_thigh">
    <visual>
      <origin xyz="0 0 0" rpy="0 0 0" />
      <geometry>
        <mesh filename="package://legged_fire_description/meshes/HR_Thigh.STL" />
      </geometry>
      <!-- <material name="">
        <color rgba="0.79216 0.81961 0.93333 1" />
      </material> -->
      <material name="green"/>
    </visual>
    <collision>
      <origin xyz="0 -0.11 0" rpy="1.57 0 0" />
      <geometry>
        <cylinder length="0.12" radius="0.07"/>
      </geometry>
    </collision>
    <collision>
      <origin xyz="-0.035 -0.14 -0.16" rpy="0 0 0" />
      <geometry>
        <box size="0.055 0.06 0.20"/>
      </geometry>
    </collision>
    <collision>
      <origin xyz="-0.017 -0.14 -0.325" rpy="0 -0.40 0" />
      <geometry>
        <box size="0.030 0.06 0.13"/>
      </geometry>
    </collision>
    <inertial>
      <origin xyz="-0.0 -0.11 -0.16" rpy="0 0 0" />
      <mass value="4.170" />
      <inertia ixx="0.071" ixy="0.0" ixz="0.0" iyy="0.077" iyz="0.0" izz="0.0081" />
    </inertial>
  </link>
  <joint name="RR_calf_joint" type="revolute">
    <origin xyz="0 -0.11514 -0.36702" rpy="0 0 0" />
    <parent link="RR_thigh" />
    <child link="RR_calf" />
    <axis xyz="0 1 0" />
    <dynamics damping="0.0" bfriction="0.2"/>
    <limit effort="80.0" lower="-2.818" upper="0" velocity="20.06"/>
  </joint>
  <link name="RR_calf">
    <visual>
      <origin xyz="0 0 0" rpy="0 0 0" />
      <geometry>
        <mesh filename="package://legged_fire_description/meshes/HR_Knee.STL" />
      </geometry>
      <!-- <material name="">
        <color rgba="0.79216 0.81961 0.93333 1" />
      </material> -->
      <material name="brown"/>
    </visual>
    <!-- <collision>
      <origin xyz="0 0 0" rpy="0 0 0" />
      <geometry>
        <mesh filename="package://legged_fire_description/meshes/HR_Knee.STL" />
      </geometry>
    </collision> -->
    <!-- <collision>
      <origin xyz="-0.01 -0.02 -0.07" rpy="0 -0.40 0" />
      <geometry>
        <box size="0.02 0.04 0.18"/>
      </geometry>
    </collision> -->
    <collision>
      <origin xyz="0.03 -0.02 -0.23" rpy="0 0 0" />
      <geometry>
        <box size="0.02 0.04 0.10"/>
      </geometry>
    </collision>
    <inertial>
      <origin xyz="0.0 -0.0225 -0.16" rpy="0 0 0" />
      <mass value="0.715" />
      <inertia ixx="0.0062" ixy="0.0" ixz="0.0" iyy="0.0062" iyz="0.0" izz="0.000133" />
    </inertial>
  </link>
  <joint name="RR_foot_fixed" type="fixed" dont_collapse="true">
    <origin xyz="0.0051604 -0.021519 -0.33117" rpy="0 0 0" />
    <parent link="RR_calf" />
    <child link="RR_FOOT" />
    <axis xyz="0 0 0" />
  </joint>
  <gazebo reference="RR_foot_fixed">
    <disableFixedJointLumping>true</disableFixedJointLumping>
  </gazebo>
  <link name="RR_FOOT">
    <visual>
      <origin xyz="0 0 0" rpy="0 0.62 0" />
      <geometry>
        <mesh filename="package://legged_fire_description/meshes/HR_Ankle.STL" />
      </geometry>
      <!-- <material name="">
        <color rgba="0 0 0 1" />
      </material> -->
      <material name="black"/>
    </visual>
    <!-- <collision>
      <origin xyz="0 0 0" rpy="0 0 0" />
      <geometry>
        <mesh filename="package://legged_fire_description/meshes/HR_Ankle.STL" />
      </geometry>
    </collision> -->
    <collision>
      <origin xyz="-0.010 0 -0.017" rpy="0 0 0" />
      <geometry>
        <sphere radius="0.022"/>
      </geometry>
    </collision>
    <inertial>
      <origin xyz="-0.012 0.0 -0.0175" rpy="0 0.62 0" />
      <mass value="0.05" />
      <inertia ixx="0.000008" ixy="0.0" ixz="0.0" iyy="0.000008" iyz="0.0" izz="0.000008" />
    </inertial>
  </link>
  <joint name="RL_hip_joint" type="revolute">
    <origin xyz="-0.2655 0.076 0" rpy="0 0 0" />
    <parent link="base" />
    <child link="RL_hip" />
    <axis xyz="1 0 0" />
    <dynamics damping="0.0" bfriction="0.2"/>
    <limit effort="80.0" lower="-1" upper="1" velocity="30.1"/>
  </joint>
  <link name="RL_hip">
    <visual>
      <origin xyz="0 0 0" rpy="0 0 0" />
      <geometry>
        <mesh filename="package://legged_fire_description/meshes/FL_Hip.STL" />
      </geometry>
      <!-- <material name="">
        <color rgba="0.79216 0.81961 0.93333 1" />
      </material> -->
      <material name="blue"/>
    </visual>
    <!-- <collision>
      <origin xyz="0 0 0" rpy="0 0 0" />
      <geometry>
        <mesh filename="package://legged_fire_description/meshes/FL_Hip.STL" />
      </geometry>
    </collision> -->
    <inertial>
      <origin xyz="-0.12 0.005 -0.0" rpy="0 0 0" />
      <mass value="2.640" />
      <inertia ixx="0.0049" ixy="0.0" ixz="0.0" iyy="0.0065" iyz="0.0" izz="0.0049" />
    </inertial>
  </link>
  <joint name="RL_thigh_joint" type="revolute">
    <origin xyz="-0.121 0.013 0" rpy="0 0 0" />
    <parent link="RL_hip" />
    <child link="RL_thigh" />
    <axis xyz="0 1 0" />
    <dynamics damping="0.0" bfriction="0.2"/>
    <limit effort="80.0" lower="-3" upper="4.501" velocity="30.1"/>
  </joint>
  <link name="RL_thigh">
    <visual>
      <origin xyz="0 0 0" rpy="0 0 0" />
      <geometry>
        <mesh filename="package://legged_fire_description/meshes/HL_Thigh.STL" />
      </geometry>
      <!-- <material name="">
        <color rgba="0.79216 0.81961 0.93333 1" />
      </material> -->
      <material name="green"/>
    </visual>
    <collision>
      <origin xyz="0 0.11 0" rpy="1.57 0 0" />
      <geometry>
        <cylinder length="0.12" radius="0.07"/>
      </geometry>
    </collision>
    <collision>
      <origin xyz="-0.035 0.14 -0.16" rpy="0 0 0" />
      <geometry>
        <box size="0.055 0.06 0.20"/>
      </geometry>
    </collision>
    <collision>
      <origin xyz="-0.017 0.14 -0.325" rpy="0 -0.40 0" />
      <geometry>
        <box size="0.030 0.06 0.13"/>
      </geometry>
    </collision>
    <inertial>
      <origin xyz="-0.0 0.11 -0.16" rpy="0 0 0" />
      <mass value="4.170" />
      <inertia ixx="0.071" ixy="0.0" ixz="0.0" iyy="0.077" iyz="0.0" izz="0.0081" />
    </inertial>
  </link>
  <joint name="RL_calf_joint" type="revolute">
    <origin xyz="0 0.11514 -0.36702" rpy="0 0 0" />
    <parent link="RL_thigh" />
    <child link="RL_calf" />
    <axis xyz="0 -1 0" />
    <dynamics damping="0.0" bfriction="0.2"/>
    <limit effort="80.0" lower="-2.818" upper="0" velocity="20.06"/>
  </joint>
  <link name="RL_calf">
    <visual>
      <origin xyz="0 0 0" rpy="0 0 0" />
      <geometry>
        <mesh filename="package://legged_fire_description/meshes/HL_Knee.STL" />
      </geometry>
      <!-- <material name="">
        <color rgba="0.79216 0.81961 0.93333 1" />
      </material> -->
      <material name="brown"/>
    </visual>
    <!-- <collision>
      <origin xyz="0 0 0" rpy="0 0 0" />
      <geometry>
        <mesh filename="package://legged_fire_description/meshes/HL_Knee.STL" />
      </geometry>
    </collision> -->
    <collision>
      <origin xyz="-0.01 0.02 -0.07" rpy="0 -0.40 0" />
      <geometry>
        <box size="0.02 0.04 0.18"/>
      </geometry>
    </collision>
    <collision>
      <origin xyz="0.03 0.02 -0.23" rpy="0 0 0" />
      <geometry>
        <box size="0.02 0.04 0.10"/>
      </geometry>
    </collision>
    <inertial>
      <origin xyz="0.0 0.0225 -0.16" rpy="0 0 0" />
      <mass value="0.715" />
      <inertia ixx="0.0062" ixy="0.0" ixz="0.0" iyy="0.0062" iyz="0.0" izz="0.000133" />
    </inertial>
  </link>
  <joint name="RL_foot_fixed" type="fixed" dont_collapse="true">
    <origin xyz="0.0051604 0.021519 -0.33117" rpy="0 0 0" />
    <parent link="RL_calf" />
    <child link="RL_FOOT" />
    <axis xyz="0 0 0" />
  </joint>
  <gazebo reference="RL_foot_fixed">
    <disableFixedJointLumping>true</disableFixedJointLumping>
  </gazebo>
  <link name="RL_FOOT">
    <visual>
      <origin xyz="0 0 0" rpy="0 0.62 0" />
      <geometry>
        <mesh filename="package://legged_fire_description/meshes/HL_Ankle.STL" />
      </geometry>
      <!-- <material name="">
        <color rgba="0 0 0 1" />
      </material> -->
      <material name="black"/>
    </visual>
    <!-- <collision>
      <origin xyz="0 0 0" rpy="0 0 0" />
      <geometry>
        <mesh filename="package://legged_fire_description/meshes/HL_Ankle.STL" />
      </geometry>
    </collision> -->
    <collision>
      <origin xyz="-0.010 0 -0.017" rpy="0 0 0" />
      <geometry>
        <sphere radius="0.022"/>
      </geometry>
    </collision>
    <inertial>
      <origin xyz="-0.012 0.0 -0.0175" rpy="0 0.62 0" />
      <mass value="0.05" />
      <inertia ixx="0.000008" ixy="0.0" ixz="0.0" iyy="0.000008" iyz="0.0" izz="0.000008" />
    </inertial>
  </link>
  <transmission name="LF_HAA_tran">
    <type>transmission_interface/SimpleTransmission</type>
    <joint name="FL_hip_joint">
      <hardwareInterface>hardware_interface/EffortJointInterface</hardwareInterface>
    </joint>
    <actuator name="LF_HAA_motor">
      <hardwareInterface>hardware_interface/EffortJointInterface</hardwareInterface>
      <mechanicalReduction>1</mechanicalReduction>
    </actuator>
  </transmission>
  <transmission name="LF_HFE_tran">
    <type>transmission_interface/SimpleTransmission</type>
    <joint name="FL_thigh_joint">
      <hardwareInterface>hardware_interface/EffortJointInterface</hardwareInterface>
    </joint>
    <actuator name="LF_HFE_motor">
      <hardwareInterface>hardware_interface/EffortJointInterface</hardwareInterface>
      <mechanicalReduction>1</mechanicalReduction>
    </actuator>
  </transmission>
  <transmission name="LF_KFE_tran">
    <type>transmission_interface/SimpleTransmission</type>
    <joint name="FL_calf_joint">
      <hardwareInterface>hardware_interface/EffortJointInterface</hardwareInterface>
    </joint>
    <actuator name="LF_KFE_motor">
      <hardwareInterface>hardware_interface/EffortJointInterface</hardwareInterface>
      <mechanicalReduction>1</mechanicalReduction>
    </actuator>
  </transmission>
  <transmission name="LH_HAA_tran">
    <type>transmission_interface/SimpleTransmission</type>
    <joint name="RL_hip_joint">
      <hardwareInterface>hardware_interface/EffortJointInterface</hardwareInterface>
    </joint>
    <actuator name="LH_HAA_motor">
      <hardwareInterface>hardware_interface/EffortJointInterface</hardwareInterface>
      <mechanicalReduction>1</mechanicalReduction>
    </actuator>
  </transmission>
  <transmission name="LH_HFE_tran">
    <type>transmission_interface/SimpleTransmission</type>
    <joint name="RL_thigh_joint">
      <hardwareInterface>hardware_interface/EffortJointInterface</hardwareInterface>
    </joint>
    <actuator name="LH_HFE_motor">
      <hardwareInterface>hardware_interface/EffortJointInterface</hardwareInterface>
      <mechanicalReduction>1</mechanicalReduction>
    </actuator>
  </transmission>
  <transmission name="LH_KFE_tran">
    <type>transmission_interface/SimpleTransmission</type>
    <joint name="RL_calf_joint">
      <hardwareInterface>hardware_interface/EffortJointInterface</hardwareInterface>
    </joint>
    <actuator name="LH_KFE_motor">
      <hardwareInterface>hardware_interface/EffortJointInterface</hardwareInterface>
      <mechanicalReduction>1</mechanicalReduction>
    </actuator>
  </transmission>
  <transmission name="RF_HAA_tran">
    <type>transmission_interface/SimpleTransmission</type>
    <joint name="FR_hip_joint">
      <hardwareInterface>hardware_interface/EffortJointInterface</hardwareInterface>
    </joint>
    <actuator name="RF_HAA_motor">
      <hardwareInterface>hardware_interface/EffortJointInterface</hardwareInterface>
      <mechanicalReduction>1</mechanicalReduction>
    </actuator>
  </transmission>
  <transmission name="RF_HFE_tran">
    <type>transmission_interface/SimpleTransmission</type>
    <joint name="FR_thigh_joint">
      <hardwareInterface>hardware_interface/EffortJointInterface</hardwareInterface>
    </joint>
    <actuator name="RF_HFE_motor">
      <hardwareInterface>hardware_interface/EffortJointInterface</hardwareInterface>
      <mechanicalReduction>1</mechanicalReduction>
    </actuator>
  </transmission>
  <transmission name="RF_KFE_tran">
    <type>transmission_interface/SimpleTransmission</type>
    <joint name="FR_calf_joint">
      <hardwareInterface>hardware_interface/EffortJointInterface</hardwareInterface>
    </joint>
    <actuator name="RF_KFE_motor">
      <hardwareInterface>hardware_interface/EffortJointInterface</hardwareInterface>
      <mechanicalReduction>1</mechanicalReduction>
    </actuator>
  </transmission>
  <transmission name="RH_HAA_tran">
    <type>transmission_interface/SimpleTransmission</type>
    <joint name="RR_hip_joint">
      <hardwareInterface>hardware_interface/EffortJointInterface</hardwareInterface>
    </joint>
    <actuator name="RH_HAA_motor">
      <hardwareInterface>hardware_interface/EffortJointInterface</hardwareInterface>
      <mechanicalReduction>1</mechanicalReduction>
    </actuator>
  </transmission>
  <transmission name="RH_HFE_tran">
    <type>transmission_interface/SimpleTransmission</type>
    <joint name="RR_thigh_joint">
      <hardwareInterface>hardware_interface/EffortJointInterface</hardwareInterface>
    </joint>
    <actuator name="RH_HFE_motor">
      <hardwareInterface>hardware_interface/EffortJointInterface</hardwareInterface>
      <mechanicalReduction>1</mechanicalReduction>
    </actuator>
  </transmission>
  <transmission name="RH_KFE_tran">
    <type>transmission_interface/SimpleTransmission</type>
    <joint name="RR_calf_joint">
      <hardwareInterface>hardware_interface/EffortJointInterface</hardwareInterface>
    </joint>
    <actuator name="RH_KFE_motor">
      <hardwareInterface>hardware_interface/EffortJointInterface</hardwareInterface>
      <mechanicalReduction>1</mechanicalReduction>
    </actuator>
  </transmission>
</robot>
