<?xml version="1.0" ?>
<!-- =================================================================================== -->
<!-- |    This document was autogenerated by xacro from /home/bridge/Bridge_hub/leg_db_ws/src/legged_debugger/legged_examples/legged_base/legged_base_description/urdf/robot_sim.xacro | -->
<!-- |    EDITING THIS FILE BY HAND IS NOT RECOMMENDED                                 | -->
<!-- =================================================================================== -->
<robot name="RobotDog">
  <!-- ros_control plugin -->
  <gazebo>
    <plugin filename="liblegged_hw_sim.so" name="gazebo_ros_control">
      <robotNamespace>/</robotNamespace>
      <robotParam>legged_robot_description</robotParam>
      <robotSimType>legged_gazebo/LeggedHWSim</robotSimType>
    </plugin>
  </gazebo>
  <gazebo>
    <plugin filename="libgazebo_ros_p3d.so" name="p3d_base_controller">
      <alwaysOn>true</alwaysOn>
      <updateRate>500.0</updateRate>
      <bodyName>base</bodyName>
      <topicName>ground_truth/state</topicName>
      <gaussianNoise>0</gaussianNoise>
      <frameName>world</frameName>
      <xyzOffsets>0 0 0</xyzOffsets>
      <rpyOffsets>0 0 0</rpyOffsets>
    </plugin>
  </gazebo>
  <material name="black">
    <color rgba="0.0 0.0 0.0 1.0"/>
  </material>
  <material name="blue">
    <color rgba="0.0 0.0 0.8 1.0"/>
  </material>
  <material name="green">
    <color rgba="0.0 0.8 0.0 1.0"/>
  </material>
  <material name="grey">
    <color rgba="0.2 0.2 0.2 1.0"/>
  </material>
  <material name="silver">
    <color rgba="0.913725490196 0.913725490196 0.847058823529 1.0"/>
  </material>
  <material name="orange">
    <!-- <color rgba="1.0 0.423529411765 0.0392156862745 1.0"/> -->
    <color rgba="0.12 0.15 0.2 1.0"/>
  </material>
  <material name="brown">
    <color rgba="0.870588235294 0.811764705882 0.764705882353 1.0"/>
  </material>
  <material name="red">
    <color rgba="0.8 0.0 0.0 1.0"/>
  </material>
  <material name="white">
    <color rgba="1.0 1.0 1.0 1.0"/>
  </material>

  <!-- <link name="odom"/>

  <joint name="odom_joint" type="fixed">
    <parent link="odom"/>
    <child link="base"/>
    <origin rpy="0 0 0" xyz="0 0 0.0"/>
  </joint> -->

  <link name="base">
    <inertial>
      <origin xyz="0.0 0.0 0.0" rpy="0 0 0" />
      <mass value="12.40" />
      <inertia ixx="0.1632" ixy="0.0" ixz="0.0" iyy="0.342653" iyz="0.0" izz="0.39432" />
    </inertial>
    <visual>
      <origin xyz="0 0 0" rpy="0 0 0" />
      <geometry>
        <mesh filename="package://legged_fire_description/meshes/Base.STL" />
      </geometry>
      <!-- <material name="">
        <color rgba="0.79216 0.81961 0.93333 1" />
      </material> -->
      <material name="grey"/>
    </visual>
    <!-- <collision>
      <origin xyz="0.025 0 0" rpy="0 0 0" />
      <geometry>
        <mesh filename="package://legged_fire_description/meshes/Base.STL" />
        <box size="1.075 0.10 0.18"/>
      </geometry>
    </collision> -->
    <collision>
      <origin xyz="0.0 0 0" rpy="0 0 0" />
      <geometry>
        <box size="0.55 0.28 0.18"/>
      </geometry>
    </collision>
    <collision>
      <origin xyz="0.42 0 0" rpy="0 0 0" />
      <geometry>
        <box size="0.25 0.12 0.18"/>
      </geometry>
    </collision>
    <collision>
      <origin xyz="-0.40 0 0" rpy="0 0 0" />
      <geometry>
        <box size="0.20 0.12 0.18"/>
      </geometry>
    </collision>
  </link>
  <joint name="base_imu_joint" type="fixed">
    <origin rpy="0. 0. 0." xyz="0. 0. 0."/>
    <parent link="base"/>
    <child link="base_imu"/>
  </joint>
  <gazebo reference="base_imu_joint">
    <disableFixedJointLumping>true</disableFixedJointLumping>
  </gazebo>
  <!-- Imu link -->
  <link name="base_imu">
    <inertial>
      <mass value="0.01"/>
      <origin rpy="0 0 0" xyz="0 0 0"/>
      <inertia ixx="0.000001" ixy="0" ixz="0" iyy="0.000001" iyz="0" izz="0.000001"/>
    </inertial>
    <visual>
      <origin rpy="0 0 0" xyz="0 0 0"/>
      <geometry>
        <box size="0.015 0.015 0.004"/>
      </geometry>
    </visual>
    <material name="orange">
      <color rgba="255 108 10 255"/>
    </material>
  </link>
  <joint name="camera_joint" type="fixed">
    <origin xyz="0.55 0 -0.01" rpy="0 0 0" />
    <parent link="base"/>
    <child link="camera"/>
    <origin rpy="0 0 0" xyz="0 0 0.0"/>
  </joint>

  <link name="camera"/>

  <link name="LF_hip">
    <inertial>
      <origin xyz="0.12 0.005 -0.0" rpy="0 0 0" />
      <mass value="2.640" />
      <inertia ixx="0.0049" ixy="0.0" ixz="0.0" iyy="0.0065" iyz="0.0" izz="0.0049" />
    </inertial>
    <visual>
      <origin xyz="0 0 0" rpy="0 0 0" />
      <geometry>
        <mesh filename="package://legged_fire_description/meshes/FL_Hip.STL" />
      </geometry>
      <!-- <material name="">
        <color rgba="0.79216 0.81961 0.93333 1" />
      </material> -->
      <material name="blue"/>
    </visual>
    <!-- <collision>
      <origin xyz="0 0 0" rpy="0 0 0" />
      <geometry>
        <mesh filename="package://legged_fire_description/meshes/LF_HAA.STL" />
      </geometry>
    </collision> -->
  </link>
  <joint name="LF_HAA" type="revolute">
    <origin xyz="0.2655 0.076 0" rpy="0 0 0" />
    <parent link="base" />
    <child link="LF_hip" />
    <axis xyz="1 0 0" />
    <limit lower="-0.5" upper="0.5" effort="80" velocity="8" />
  </joint>
  <link name="LF_thigh">
    <inertial>
      <origin xyz="-0.0 0.11 -0.16" rpy="0 0 0" />
      <mass value="4.170" />
      <inertia ixx="0.071" ixy="0.0" ixz="0.0" iyy="0.077" iyz="0.0" izz="0.0081" />
    </inertial>
    <visual>
      <origin xyz="0 0 0" rpy="0 0 0" />
      <geometry>
        <mesh filename="package://legged_fire_description/meshes/FL_Thigh.STL" />
      </geometry>
      <!-- <material name="">
        <color rgba="0.79216 0.81961 0.93333 1" />
      </material> -->
      <material name="green"/>
    </visual>
    <collision>
      <origin xyz="0 0.11 0" rpy="1.57 0 0" />
      <geometry>
        <cylinder length="0.12" radius="0.07"/>
      </geometry>
    </collision>
    <collision>
      <origin xyz="-0.035 0.14 -0.16" rpy="0 0 0" />
      <geometry>
        <box size="0.055 0.06 0.20"/>
      </geometry>
    </collision>
    <collision>
      <origin xyz="-0.017 0.14 -0.325" rpy="0 -0.40 0" />
      <geometry>
        <box size="0.030 0.06 0.13"/>
      </geometry>
    </collision>
  </link>
  <joint name="LF_HFE" type="revolute">
    <origin xyz="0.121 0.013 0" rpy="0 0 0" />
    <parent link="LF_hip" />
    <child link="LF_thigh" />
    <axis xyz="0 1 0" />
    <limit lower="-3.14" upper="3.14" effort="80" velocity="8" />
  </joint>
  <link name="LF_calf">
    <inertial>
      <origin xyz="0.0 0.0225 -0.16" rpy="0 0 0" />
      <mass value="0.715" />
      <inertia ixx="0.0062" ixy="0.0" ixz="0.0" iyy="0.0062" iyz="0.0" izz="0.000133" />
    </inertial>
    <visual>
      <origin xyz="0 0 0" rpy="0 0 0" />
      <geometry>
        <mesh filename="package://legged_fire_description/meshes/LF_Knee.STL" />
      </geometry>
      <!-- <material name="">
        <color rgba="0.79216 0.81961 0.93333 1" />
      </material> -->
      <material name="brown"/>
    </visual>
    <!-- <collision>
      <origin xyz="-0.01 0.02 -0.07" rpy="0 -0.40 0" />
      <geometry>
        <box size="0.02 0.04 0.18"/>
      </geometry>
    </collision> -->
    <collision>
      <origin xyz="0.03 0.02 -0.23" rpy="0 0 0" />
      <geometry>
        <box size="0.02 0.04 0.10"/>
      </geometry>
    </collision>
  </link>
  <joint name="LF_KFE" type="revolute">
    <origin xyz="0 0.11514 -0.36702" rpy="0 0 0" />
    <parent link="LF_thigh" />
    <child link="LF_calf" />
    <axis xyz="0 1 0" />
    <limit lower="-2.7" upper="-1.57" effort="80" velocity="8" />
  </joint>
  <link name="LF_FOOT">
    <inertial>
      <origin xyz="-0.012 0.0 -0.0175" rpy="0 0.62 0" />
      <mass value="0.05" />
      <inertia ixx="0.000008" ixy="0.0" ixz="0.0" iyy="0.000008" iyz="0.0" izz="0.000008" />
    </inertial>
    <visual>
      <origin xyz="0 0 0" rpy="0 0.62 0" />
      <geometry>
        <mesh filename="package://legged_fire_description/meshes/LF_Ankle.STL" />
      </geometry>
      <!-- <material name="">
        <color rgba="0 0 0 1" />
      </material> -->
      <material name="black"/>
    </visual>
    <!-- <collision>
      <origin xyz="0 0 0" rpy="0 0 0" />
      <geometry>
        <mesh filename="package://legged_fire_description/meshes/LF_Ankle.STL" />
      </geometry>
    </collision> -->
    <collision>
      <origin xyz="-0.010 0 -0.017" rpy="0 0 0" />
      <geometry>
        <sphere radius="0.022"/>
      </geometry>
    </collision>
  </link>
  <joint name="LF_fixed" type="fixed" dont_collapse="true">
    <origin xyz="0.0051604 0.021519 -0.33117" rpy="0 0 0" />
    <parent link="LF_calf" />
    <child link="LF_FOOT" />
    <axis xyz="0 0 0" />
  </joint>

  <link name="RF_hip">
    <inertial>
      <origin xyz="0.12 -0.005 0.0" rpy="0 0 0" />
      <mass value="2.640" />
      <inertia ixx="0.0049" ixy="0.0" ixz="0.0" iyy="0.0065" iyz="0.0" izz="0.0049" />
    </inertial>
    <visual>
      <origin xyz="0 0 0" rpy="0 0 0" />
      <geometry>
        <mesh filename="package://legged_fire_description/meshes/FR_Hip.STL" />
      </geometry>
      <!-- <material name="">
        <color rgba="0.79216 0.81961 0.93333 1" />
      </material> -->
      <material name="blue"/>
    </visual>
    <!-- <collision>
      <origin xyz="0 0 0" rpy="0 0 0" />
      <geometry>
        <mesh filename="package://legged_fire_description/meshes/RF_HAA.STL" />
      </geometry>
    </collision> -->
  </link>
  <joint name="RF_HAA" type="revolute">
    <origin xyz="0.2655 -0.076 0" rpy="0 0 0" />
    <parent link="base" />
    <child link="RF_hip" />
    <axis xyz="1 0 0" />
    <limit lower="-0.5" upper="0.5" effort="80" velocity="8" />
  </joint>
  <link name="RF_thigh">
    <inertial>
      <origin xyz="-0.0 -0.11 -0.16" rpy="0 0 0" />
      <mass value="4.170" />
      <inertia ixx="0.071" ixy="0.0" ixz="0.0" iyy="0.077" iyz="0.0" izz="0.0081" />
    </inertial>
    <visual>
      <origin xyz="0 0 0" rpy="0 0 0" />
      <geometry>
        <mesh filename="package://legged_fire_description/meshes/HR_Thigh.STL" />
      </geometry>
      <!-- <material name="">
        <color rgba="0.79216 0.81961 0.93333 1" />
      </material> -->
      <material name="green"/>
    </visual>
    <collision>
      <origin xyz="0 -0.11 0" rpy="1.57 0 0" />
      <geometry>
        <cylinder length="0.12" radius="0.07"/>
      </geometry>
    </collision>
    <collision>
      <origin xyz="-0.035 -0.14 -0.16" rpy="0 0 0" />
      <geometry>
        <box size="0.055 0.06 0.20"/>
      </geometry>
    </collision>
    <collision>
      <origin xyz="-0.017 -0.14 -0.325" rpy="0 -0.40 0" />
      <geometry>
        <box size="0.030 0.06 0.13"/>
      </geometry>
    </collision>
  </link>
  <joint name="RF_HFE" type="revolute">
    <origin xyz="0.121 -0.013 0" rpy="0 0 0" />
    <parent link="RF_hip" />
    <child link="RF_thigh" />
    <axis xyz="0 1 0" />
    <limit lower="-3.14" upper="3.14" effort="80" velocity="8" />
  </joint>
  <link name="RF_calf">
    <inertial>
      <origin xyz="0.0 -0.0225 -0.16" rpy="0 0 0" />
      <mass value="0.715" />
      <inertia ixx="0.0062" ixy="0.0" ixz="0.0" iyy="0.0062" iyz="0.0" izz="0.000133" />
    </inertial>
    <visual>
      <origin xyz="0 0 0" rpy="0 0 0" />
      <geometry>
        <mesh filename="package://legged_fire_description/meshes/RF_Knee.STL" />
      </geometry>
      <!-- <material name="">
        <color rgba="0.79216 0.81961 0.93333 1" />
      </material> -->
      <material name="brown"/>
    </visual>
    <!-- <collision>
      <origin xyz="0 0 0" rpy="0 0 0" />
      <geometry>
        <mesh filename="package://legged_fire_description/meshes/RF_Knee.STL" />
      </geometry>
    </collision> -->
    <!-- <collision>
      <origin xyz="-0.01 -0.02 -0.07" rpy="0 -0.40 0" />
      <geometry>
        <box size="0.02 0.04 0.18"/>
      </geometry>
    </collision> -->
    <collision>
      <origin xyz="0.03 -0.02 -0.23" rpy="0 0 0" />
      <geometry>
        <box size="0.02 0.04 0.10"/>
      </geometry>
    </collision>
  </link>
  <joint name="RF_KFE" type="revolute">
    <origin xyz="0.0 -0.11514 -0.36702" rpy="0 0 0" />
    <parent link="RF_thigh" />
    <child link="RF_calf" />
    <axis xyz="0 1 0" />
    <limit lower="-2.7" upper="-1.57" effort="80" velocity="8" />
  </joint>
  <link name="RF_FOOT">
    <inertial>
      <origin xyz="-0.012 0.0 -0.0175" rpy="0 0.62 0" />
      <mass value="0.05" />
      <inertia ixx="0.000008" ixy="0.0" ixz="0.0" iyy="0.000008" iyz="0.0" izz="0.000008" />
    </inertial>
    <visual>
      <origin xyz="0 0 0" rpy="0 0.62 0" />
      <geometry>
        <mesh filename="package://legged_fire_description/meshes/RF_Ankle.STL" />
      </geometry>
      <!-- <material name="">
        <color rgba="0 0 0 1" />
      </material> -->
      <material name="black"/>
    </visual>
    <!-- <collision>
      <origin xyz="0 0 0" rpy="0 0 0" />
      <geometry>
        <mesh filename="package://legged_fire_description/meshes/RF_Ankle.STL" />
      </geometry>
    </collision> -->
    <collision>
      <origin xyz="-0.010 0 -0.017" rpy="0 0 0" />
      <geometry>
        <sphere radius="0.022"/>
      </geometry>
    </collision>
  </link>
  <joint name="RF_fixed" type="fixed" dont_collapse="true">
    <origin xyz="0.0051604 -0.021519 -0.33117" rpy="0 0 0" />
    <parent link="RF_calf" />
    <child link="RF_FOOT" />
    <axis xyz="0 0 0" />
  </joint>
  <link name="LH_hip">
    <inertial>
      <origin xyz="-0.12 0.005 -0.0" rpy="0 0 0" />
      <mass value="2.640" />
      <inertia ixx="0.0049" ixy="0.0" ixz="0.0" iyy="0.0065" iyz="0.0" izz="0.0049" />
    </inertial>
    <visual>
      <origin xyz="0 0 0" rpy="0 0 0" />
      <geometry>
        <mesh filename="package://legged_fire_description/meshes/HL_Hip.STL" />
      </geometry>
      <!-- <material name="">
        <color rgba="0.79216 0.81961 0.93333 1" />
      </material> -->
      <material name="blue"/>
    </visual>
    <!-- <collision>
      <origin xyz="0 0 0" rpy="0 0 0" />
      <geometry>
        <mesh filename="package://legged_fire_description/meshes/HL_HAA.STL" />
      </geometry>
    </collision> -->
  </link>
  <joint name="LH_HAA" type="revolute">
    <origin xyz="-0.2655 0.076 0" rpy="0 0 0" />
    <parent link="base" />
    <child link="LH_hip" />
    <axis xyz="1 0 0" />
    <limit lower="-0.5" upper="0.5" effort="80" velocity="8" />
  </joint>
  <link name="LH_thigh">
    <inertial>
      <origin xyz="-0.0 0.11 -0.16" rpy="0 0 0" />
      <mass value="4.170" />
      <inertia ixx="0.071" ixy="0.0" ixz="0.0" iyy="0.077" iyz="0.0" izz="0.0081" />
    </inertial>
    <visual>
      <origin xyz="0 0 0" rpy="0 0 0" />
      <geometry>
        <mesh filename="package://legged_fire_description/meshes/HL_Thigh.STL" />
      </geometry>
      <!-- <material name="">
        <color rgba="0.79216 0.81961 0.93333 1" />
      </material> -->
      <material name="green"/>
    </visual>
    <collision>
      <origin xyz="0 0.11 0" rpy="1.57 0 0" />
      <geometry>
        <cylinder length="0.12" radius="0.07"/>
      </geometry>
    </collision>
    <collision>
      <origin xyz="-0.035 0.14 -0.16" rpy="0 0 0" />
      <geometry>
        <box size="0.055 0.06 0.20"/>
      </geometry>
    </collision>
    <collision>
      <origin xyz="-0.017 0.14 -0.325" rpy="0 -0.40 0" />
      <geometry>
        <box size="0.030 0.06 0.13"/>
      </geometry>
    </collision>
  </link>
  <joint name="LH_HFE" type="revolute">
    <origin xyz="-0.121 0.013 0" rpy="0 0 0" />
    <parent link="LH_hip" />
    <child link="LH_thigh" />
    <axis xyz="0 1 0" />
    <limit lower="-3.14" upper="3.14" effort="80" velocity="8" />
  </joint>
  <link name="LH_calf">
    <inertial>
      <origin xyz="0.0 0.0225 -0.16" rpy="0 0 0" />
      <mass value="0.715" />
      <inertia ixx="0.0062" ixy="0.0" ixz="0.0" iyy="0.0062" iyz="0.0" izz="0.000133" />
    </inertial>
    <visual>
      <origin xyz="0 0 0" rpy="0 0 0" />
      <geometry>
        <mesh filename="package://legged_fire_description/meshes/HL_Knee.STL" />
      </geometry>
      <!-- <material name="">
        <color rgba="0.79216 0.81961 0.93333 1" />
      </material> -->
      <material name="brown"/>
    </visual>
    <!-- <collision>
      <origin xyz="0 0 0" rpy="0 0 0" />
      <geometry>
        <mesh filename="package://legged_fire_description/meshes/HL_Knee.STL" />
      </geometry>
    </collision> -->
    <!-- <collision>
      <origin xyz="-0.01 0.02 -0.07" rpy="0 -0.40 0" />
      <geometry>
        <box size="0.02 0.04 0.18"/>
      </geometry>
    </collision> -->
    <collision>
      <origin xyz="0.03 0.02 -0.23" rpy="0 0 0" />
      <geometry>
        <box size="0.02 0.04 0.10"/>
      </geometry>
    </collision>
  </link>
  <joint name="LH_KFE" type="revolute">
    <origin xyz="0 0.11514 -0.36702" rpy="0 0 0" />
    <parent link="LH_thigh" />
    <child link="LH_calf" />
    <axis xyz="0 1 0" />
    <limit effort="80.0" lower="-2.818" upper="0" velocity="20.06"/>
  </joint>
  <link name="LH_FOOT">
    <inertial>
      <origin xyz="-0.012 0.0 -0.0175" rpy="0 0.62 0" />
      <mass value="0.05" />
      <inertia ixx="0.000008" ixy="0.0" ixz="0.0" iyy="0.000008" iyz="0.0" izz="0.000008" />
    </inertial>
    <visual>
      <origin xyz="0 0 0" rpy="0 0.62 0" />
      <geometry>
        <mesh filename="package://legged_fire_description/meshes/HL_Ankle.STL" />
      </geometry>
      <!-- <material name="">
        <color rgba="0 0 0 1" />
      </material> -->
      <material name="black"/>
    </visual>
    <!-- <collision>
      <origin xyz="0 0 0" rpy="0 0 0" />
      <geometry>
        <mesh filename="package://legged_fire_description/meshes/HL_Ankle.STL" />
      </geometry>
    </collision> -->
    <collision>
      <origin xyz="-0.010 0 -0.017" rpy="0 0 0" />
      <geometry>
        <sphere radius="0.022"/>
      </geometry>
    </collision>
  </link>
  <joint name="LH_fixed" type="fixed" dont_collapse="true">
    <origin xyz="0.0051604 0.021519 -0.33117" rpy="0 0 0" />
    <parent link="LH_calf" />
    <child link="LH_FOOT" />
    <axis xyz="0 0 0" />
  </joint>
  <link name="RH_hip">
    <inertial>
      <origin xyz="-0.12 -0.005 -0.0" rpy="0 0 0" />
      <mass value="2.640" />
      <inertia ixx="0.0049" ixy="0.0" ixz="0.0" iyy="0.0065" iyz="0.0" izz="0.0049" />
    </inertial>
    <visual>
      <origin xyz="0 0 0" rpy="0 0 0" />
      <geometry>
        <mesh filename="package://legged_fire_description/meshes/HR_Hip.STL" />
      </geometry>
      <!-- <material name="">
        <color rgba="0.79216 0.81961 0.93333 1" />
      </material> -->
      <material name="blue"/>
    </visual>
    <!-- <collision>
      <origin xyz="0 0 0" rpy="0 0 0" />
      <geometry>
        <mesh filename="package://legged_fire_description/meshes/HR_HAA.STL" />
      </geometry>
    </collision> -->
  </link>
  <joint name="RH_HAA" type="revolute">
    <origin xyz="-0.2655 -0.076 0" rpy="0 0 0" />
    <parent link="base" />
    <child link="RH_hip" />
    <axis xyz="1 0 0" />
    <limit lower="-0.5" upper="0.5" effort="80" velocity="8" />
  </joint>
  <link name="RH_thigh">
    <inertial>
      <origin xyz="-0.0 -0.11 -0.16" rpy="0 0 0" />
      <mass value="4.170" />
      <inertia ixx="0.071" ixy="0.0" ixz="0.0" iyy="0.077" iyz="0.0" izz="0.0081" />
    </inertial>
    <visual>
      <origin xyz="0 0 0" rpy="0 0 0" />
      <geometry>
        <mesh filename="package://legged_fire_description/meshes/HR_Thigh.STL" />
      </geometry>
      <!-- <material name="">
        <color rgba="0.79216 0.81961 0.93333 1" />
      </material> -->
      <material name="green"/>
    </visual>
    <collision>
      <origin xyz="0 -0.11 0" rpy="1.57 0 0" />
      <geometry>
        <cylinder length="0.12" radius="0.07"/>
      </geometry>
    </collision>
    <collision>
      <origin xyz="-0.035 -0.14 -0.16" rpy="0 0 0" />
      <geometry>
        <box size="0.055 0.06 0.20"/>
      </geometry>
    </collision>
    <collision>
      <origin xyz="-0.017 -0.14 -0.325" rpy="0 -0.40 0" />
      <geometry>
        <box size="0.030 0.06 0.13"/>
      </geometry>
    </collision>
  </link>
  <joint name="RH_HFE" type="revolute">
    <origin xyz="-0.121 -0.013 0" rpy="0 0 0" />
    <parent link="RH_hip" />
    <child link="RH_thigh" />
    <axis xyz="0 1 0" />
    <limit lower="-3.14" upper="3.14" effort="80" velocity="8" />
  </joint>
  <link name="RH_calf">
    <inertial>
      <origin xyz="0.0 -0.0225 -0.16" rpy="0 0 0" />
      <mass value="0.715" />
      <inertia ixx="0.0062" ixy="0.0" ixz="0.0" iyy="0.0062" iyz="0.0" izz="0.000133" />
    </inertial>
    <visual>
      <origin xyz="0 0 0" rpy="0 0 0" />
      <geometry>
        <mesh filename="package://legged_fire_description/meshes/HR_Knee.STL" />
      </geometry>
      <!-- <material name="">
        <color rgba="0.79216 0.81961 0.93333 1" />
      </material> -->
      <material name="brown"/>
    </visual>
    <!-- <collision>
      <origin xyz="0 0 0" rpy="0 0 0" />
      <geometry>
        <mesh filename="package://legged_fire_description/meshes/HR_Knee.STL" />
      </geometry>
    </collision> -->
    <!-- <collision>
      <origin xyz="-0.01 -0.02 -0.07" rpy="0 -0.40 0" />
      <geometry>
        <box size="0.02 0.04 0.18"/>
      </geometry>
    </collision> -->
    <collision>
      <origin xyz="0.03 -0.02 -0.23" rpy="0 0 0" />
      <geometry>
        <box size="0.02 0.04 0.10"/>
      </geometry>
    </collision>
  </link>
  <joint name="RH_KFE" type="revolute">
    <origin xyz="0 -0.11514 -0.36702" rpy="0 0 0" />
    <parent link="RH_thigh" />
    <child link="RH_calf" />
    <axis xyz="0 1 0" />
    <limit effort="80.0" lower="-2.818" upper="0" velocity="20.06"/>
  </joint>
  <link name="RH_FOOT">
    <inertial>
      <origin xyz="-0.012 0.0 -0.0175" rpy="0 0.62 0" />
      <mass value="0.05" />
      <inertia ixx="0.000008" ixy="0.0" ixz="0.0" iyy="0.000008" iyz="0.0" izz="0.000008" />
    </inertial>
    <visual>
      <origin xyz="0 0 0" rpy="0 0.62 0" />
      <geometry>
        <mesh filename="package://legged_fire_description/meshes/HR_Ankle.STL" />
      </geometry>
      <!-- <material name="">
        <color rgba="0 0 0 1" />
      </material> -->
      <material name="black"/>
    </visual>
    <!-- <collision>
      <origin xyz="0 0 0" rpy="0 0 0" />
      <geometry>
        <mesh filename="package://legged_fire_description/meshes/HR_Ankle.STL" />
      </geometry>
    </collision> -->
    <collision>
      <origin xyz="-0.010 0 -0.017" rpy="0 0 0" />
      <geometry>
        <sphere radius="0.022"/>
      </geometry>
    </collision>
  </link>
  <joint name="RH_fixed" type="fixed" dont_collapse="true">
    <origin xyz="0.0051604 -0.021519 -0.33117" rpy="0 0 0" />
    <parent link="RH_calf" />
    <child link="RH_FOOT" />
    <axis xyz="0 0 0" />
  </joint>
  <transmission name="LF_HAA_tran">
    <type>transmission_interface/SimpleTransmission</type>
    <joint name="LF_HAA">
      <hardwareInterface>hardware_interface/EffortJointInterface</hardwareInterface>
    </joint>
    <actuator name="LF_HAA_motor">
      <hardwareInterface>hardware_interface/EffortJointInterface</hardwareInterface>
      <mechanicalReduction>1</mechanicalReduction>
    </actuator>
  </transmission>
  <transmission name="LF_HFE_tran">
    <type>transmission_interface/SimpleTransmission</type>
    <joint name="LF_HFE">
      <hardwareInterface>hardware_interface/EffortJointInterface</hardwareInterface>
    </joint>
    <actuator name="LF_HFE_motor">
      <hardwareInterface>hardware_interface/EffortJointInterface</hardwareInterface>
      <mechanicalReduction>1</mechanicalReduction>
    </actuator>
  </transmission>
  <transmission name="LF_KFE_tran">
    <type>transmission_interface/SimpleTransmission</type>
    <joint name="LF_KFE">
      <hardwareInterface>hardware_interface/EffortJointInterface</hardwareInterface>
    </joint>
    <actuator name="LF_KFE_motor">
      <hardwareInterface>hardware_interface/EffortJointInterface</hardwareInterface>
      <mechanicalReduction>1</mechanicalReduction>
    </actuator>
  </transmission>
  <transmission name="LH_HAA_tran">
    <type>transmission_interface/SimpleTransmission</type>
    <joint name="LH_HAA">
      <hardwareInterface>hardware_interface/EffortJointInterface</hardwareInterface>
    </joint>
    <actuator name="LH_HAA_motor">
      <hardwareInterface>hardware_interface/EffortJointInterface</hardwareInterface>
      <mechanicalReduction>1</mechanicalReduction>
    </actuator>
  </transmission>
  <transmission name="LH_HFE_tran">
    <type>transmission_interface/SimpleTransmission</type>
    <joint name="LH_HFE">
      <hardwareInterface>hardware_interface/EffortJointInterface</hardwareInterface>
    </joint>
    <actuator name="LH_HFE_motor">
      <hardwareInterface>hardware_interface/EffortJointInterface</hardwareInterface>
      <mechanicalReduction>1</mechanicalReduction>
    </actuator>
  </transmission>
  <transmission name="LH_KFE_tran">
    <type>transmission_interface/SimpleTransmission</type>
    <joint name="LH_KFE">
      <hardwareInterface>hardware_interface/EffortJointInterface</hardwareInterface>
    </joint>
    <actuator name="LH_KFE_motor">
      <hardwareInterface>hardware_interface/EffortJointInterface</hardwareInterface>
      <mechanicalReduction>1</mechanicalReduction>
    </actuator>
  </transmission>
  <transmission name="RF_HAA_tran">
    <type>transmission_interface/SimpleTransmission</type>
    <joint name="RF_HAA">
      <hardwareInterface>hardware_interface/EffortJointInterface</hardwareInterface>
    </joint>
    <actuator name="RF_HAA_motor">
      <hardwareInterface>hardware_interface/EffortJointInterface</hardwareInterface>
      <mechanicalReduction>1</mechanicalReduction>
    </actuator>
  </transmission>
  <transmission name="RF_HFE_tran">
    <type>transmission_interface/SimpleTransmission</type>
    <joint name="RF_HFE">
      <hardwareInterface>hardware_interface/EffortJointInterface</hardwareInterface>
    </joint>
    <actuator name="RF_HFE_motor">
      <hardwareInterface>hardware_interface/EffortJointInterface</hardwareInterface>
      <mechanicalReduction>1</mechanicalReduction>
    </actuator>
  </transmission>
  <transmission name="RF_KFE_tran">
    <type>transmission_interface/SimpleTransmission</type>
    <joint name="RF_KFE">
      <hardwareInterface>hardware_interface/EffortJointInterface</hardwareInterface>
    </joint>
    <actuator name="RF_KFE_motor">
      <hardwareInterface>hardware_interface/EffortJointInterface</hardwareInterface>
      <mechanicalReduction>1</mechanicalReduction>
    </actuator>
  </transmission>
  <transmission name="RH_HAA_tran">
    <type>transmission_interface/SimpleTransmission</type>
    <joint name="RH_HAA">
      <hardwareInterface>hardware_interface/EffortJointInterface</hardwareInterface>
    </joint>
    <actuator name="RH_HAA_motor">
      <hardwareInterface>hardware_interface/EffortJointInterface</hardwareInterface>
      <mechanicalReduction>1</mechanicalReduction>
    </actuator>
  </transmission>
  <transmission name="RH_HFE_tran">
    <type>transmission_interface/SimpleTransmission</type>
    <joint name="RH_HFE">
      <hardwareInterface>hardware_interface/EffortJointInterface</hardwareInterface>
    </joint>
    <actuator name="RH_HFE_motor">
      <hardwareInterface>hardware_interface/EffortJointInterface</hardwareInterface>
      <mechanicalReduction>1</mechanicalReduction>
    </actuator>
  </transmission>
  <transmission name="RH_KFE_tran">
    <type>transmission_interface/SimpleTransmission</type>
    <joint name="RH_KFE">
      <hardwareInterface>hardware_interface/EffortJointInterface</hardwareInterface>
    </joint>
    <actuator name="RH_KFE_motor">
      <hardwareInterface>hardware_interface/EffortJointInterface</hardwareInterface>
      <mechanicalReduction>1</mechanicalReduction>
    </actuator>
  </transmission>
  <gazebo reference="RH_FOOT">
    <mu1>0.6</mu1>
    <mu2>0.6</mu2>
    <self_collide>1</self_collide>
    <material>Gazebo/DarkGrey</material>
    <kp value="1000000.0"/>
    <kd value="100.0"/>
  </gazebo>
  <gazebo reference="LH_FOOT">
    <mu1>0.6</mu1>
    <mu2>0.6</mu2>
    <self_collide>1</self_collide>
    <material>Gazebo/DarkGrey</material>
    <kp value="1000000.0"/>
    <kd value="100.0"/>
  </gazebo>
  <gazebo reference="RF_FOOT">
    <mu1>0.6</mu1>
    <mu2>0.6</mu2>
    <self_collide>1</self_collide>
    <material>Gazebo/DarkGrey</material>
    <kp value="1000000.0"/>
    <kd value="100.0"/>
  </gazebo>
  <gazebo reference="LF_FOOT">
    <mu1>0.6</mu1>
    <mu2>0.6</mu2>
    <self_collide>1</self_collide>
    <material>Gazebo/DarkGrey</material>
    <kp value="1000000.0"/>
    <kd value="100.0"/>
  </gazebo>
</robot>